<mujoco model="maurice_bot">
  <compiler angle="radian" coordinate="local" meshdir="/home/vignesh/maurice-prod/ros2_ws/src/maurice_bot/maurice_sim/meshes" eulerseq="zyx"/>
  <!-- COLLISION DISABLED: Testing external collision checker -->
  <option gravity="0 0 -9.81" />
  
  <!-- Disable all collisions globally -->
  <default>
    <geom contype="0" conaffinity="0"/>
  </default>

  <asset>
    <mesh name="base_mesh" file="base.STL" scale="1 1 1"/>
    <mesh name="link1_mesh" file="link1.STL" scale="1 1 1"/>
    <mesh name="link2_mesh" file="link2.STL" scale="1 1 1"/>
    <mesh name="link3_mesh" file="link3.STL" scale="1 1 1"/>
    <mesh name="link4_mesh" file="link4.STL" scale="1 1 1"/>
    <mesh name="link5_mesh" file="link5.STL" scale="0.001 0.001 0.001"/>
    <mesh name="link61_mesh" file="link61.STL" scale="0.001 0.001 0.001"/>
    <mesh name="link62_mesh" file="link62.STL" scale="0.001 0.001 0.001"/>
    
    <!-- Add grid texture and material -->
    <texture type="2d" name="grid" builtin="checker" rgb1=".1 .2 .3" rgb2=".2 .3 .4" width="512" height="512" mark="edge" markrgb=".8 .8 .8"/>
    <material name="grid_material" texture="grid" texrepeat="5 5" texuniform="true" reflectance=".0"/>
    
    <!-- New materials -->
    <material name="matt_black" rgba="0.05 0.05 0.05 1"/>
    <material name="bright_orange" rgba="1.0 0.5 0.0 1"/>
  </asset>

  <worldbody>
    <!-- Standard lighting setup -->
    <light name="spotlight" mode="targetbody" target="base_link" diffuse=".8 .8 .8" specular="0.3 0.3 0.3" pos="0 -1 2" cutoff="30"/>
    <light name="top" pos="0 0 10" dir="0 0 -1" diffuse=".7 .7 .7" specular="0.3 0.3 0.3"/>
    <light name="side1" pos="2 0 1" dir="-1 0 -0.5" diffuse=".5 .5 .5" specular="0.2 0.2 0.2"/>
    <light name="side2" pos="-2 0 1" dir="1 0 -0.5" diffuse=".5 .5 .5" specular="0.2 0.2 0.2"/>

    <!-- Ground plane with grid material -->
    <geom name="floor" type="plane" pos="0 0 0" size="10 10 0.1" material="grid_material"/>

    <!-- Reordering: x and y translations before yaw rotation -->
    <body name="base_root" pos="0 0 0">
      <inertial pos="0 0 0" mass="0.01" diaginertia="0.1 0.1 0.1"/>
      
      <!-- First, translation along the x-axis -->
      <joint name="base_x" type="slide" axis="1 0 0" damping="5"/>
      
      <body name="base_x" pos="0 0 0">
        <inertial pos="0 0 0" mass="0.01" diaginertia="0.1 0.1 0.1"/>
        <!-- Then, translation along the y-axis -->
        <joint name="base_y" type="slide" axis="0 1 0" damping="5"/>
        
        <body name="base_y" pos="0 0 0">
          <inertial pos="0 0 0" mass="0.01" diaginertia="0.1 0.1 0.1"/>
          <!-- Finally, apply yaw rotation -->
          <joint name="base_yaw" type="hinge" axis="0 0 1" damping="5"/>
          
          <!-- Base link and the rest of the arm -->
          <body name="base_link" pos="0 0 0">
            <inertial pos="0 0 0" mass="0.89" diaginertia="0.001 0.001 0.001"/>
            <geom name="base_geom" type="mesh" mesh="base_mesh" material="matt_black" euler="-1.5708 0 0"/>
            <camera name="camera_base" pos="0.0197 0 0.19663" 
                    quat="0.5416752 0.4545195 -0.4545195 -0.5416752" mode="fixed" fovy="80"/>
            
            <body name="link1" pos="0.086 -0.05285 0.04025">
              <inertial pos="0 0 0" mass="0.065" diaginertia="0.0001 0.0001 0.0001"/>
              <joint name="joint1" type="hinge" axis="0 0 1" limited="true" range="-3.14 3.14" damping="5"/>
              <geom name="link1_geom" type="mesh" mesh="link1_mesh" material="bright_orange" euler="0 0 1.5708"/>
              
              <body name="link2" pos="0 0 0.04225">
                <inertial pos="0 0 0" mass="0.080" diaginertia="0.0001 0.0001 0.0001"/>
                <joint name="joint2" type="hinge" axis="0 1 0" limited="true" range="-3.14 3.14" damping="5"/>
                <geom name="link2_geom" type="mesh" mesh="link2_mesh" material="matt_black" euler="1.5708 0 1.5708"/>
                
                <body name="link3" pos="0.02825 0 0.12125">
                  <inertial pos="0 0 0" mass="0.055" diaginertia="0.0001 0.0001 0.0001"/>
                  <joint name="joint3" type="hinge" axis="0 1 0" limited="true" range="-3.14 3.14" damping="5"/>
                  <geom name="link3_geom" type="mesh" mesh="link3_mesh" material="bright_orange" euler="1.5708 0 1.5708"/>
                  
                  <body name="link4" pos="0.1375 0 -0.0045">
                    <inertial pos="0 0 0" mass="0.022" diaginertia="0.00005 0.00005 0.00005"/>
                    <joint name="joint4" type="hinge" axis="0 1 0" limited="true" range="-3.14 3.14" damping="5"/>
                    <geom name="link4_geom" type="mesh" mesh="link4_mesh" material="matt_black" euler="1.5708 0 1.5708"/>
                    
                    <body name="link5" pos="0.019 0 0">
                      <inertial pos="0 0 0" mass="0.050" diaginertia="0.00005 0.00005 0.00005"/>
                      <joint name="joint5" type="hinge" axis="1 0 0" limited="true" range="-3.14 3.14" damping="5"/>
                      <geom name="link5_geom" type="mesh" mesh="link5_mesh" material="bright_orange" euler="1.5708 0 1.5708"/>
                      
                      <body name="link61" pos="0.044 -0.0091 0">
                        <inertial pos="0 0 0" mass="0.012" diaginertia="0.00002 0.00002 0.00002"/>
                        <joint name="joint6" type="hinge" axis="0 0 -1" limited="true" range="-1.57 1.57" damping="5"/>
                        <geom name="link61_geom" type="mesh" mesh="link61_mesh" material="matt_black" euler="1.5708 0 1.5708"/>
                      </body>
                      
                      <body name="link62" pos="0.044 0.0091 0">
                        <inertial pos="0 0 0" mass="0.012" diaginertia="0.00002 0.00002 0.00002"/>
                        <joint name="joint6M" type="hinge" axis="0 0 1" limited="true" range="-1.57 1.57" damping="5"/>
                        <geom name="link62_geom" type="mesh" mesh="link62_mesh" material="matt_black" euler="1.5708 0 1.5708"/>
                      </body>
                      
                      <!-- Add End Effector -->
                      <body name="ee_link" pos="0.09285 0 0">
                        <inertial pos="0 0 0" mass="0.001" diaginertia="0.00001 0.00001 0.00001"/>
                        <geom name="ee_geom" type="sphere" size="0.005" material="bright_orange"/>
                      </body>
                      
                      <body name="arm_camera_link" pos="0.00454 0 0.05448">
                        <inertial pos="0 0 0" mass="0.01" diaginertia="1e-4 1e-4 1e-4"/>
                        <camera name="camera_arm" mode="fixed" fovy="80" quat="0.6532815 0.2705981 -0.2705981 -0.6532815"/>
                      </body>
                    </body>
                  </body>
                </body>
              </body>
            </body>
          </body>
        </body>
      </body>
    </body>
  </worldbody>

  <!-- Collision settings -->
  <contact>
    <exclude name="ex_base_root_base_x" body1="base_root" body2="base_x"/>
    <exclude name="ex_base_x_base_y" body1="base_x" body2="base_y"/>
    <exclude name="ex_base_y_base_link" body1="base_y" body2="base_link"/>
    <exclude name="ex_base_link_link1" body1="base_link" body2="link1"/>
    <exclude name="ex_link1_link2" body1="link1" body2="link2"/>
    <exclude name="ex_link2_link3" body1="link2" body2="link3"/>
    <exclude name="ex_link3_link4" body1="link3" body2="link4"/>
    <exclude name="ex_link4_link5" body1="link4" body2="link5"/>
    <exclude name="ex_link5_link61" body1="link5" body2="link61"/>
    <exclude name="ex_link5_link62" body1="link5" body2="link62"/>
  </contact>
  
  <!-- Geared gripper constraint: joint6M mimics joint6 with 1:1 ratio -->
  <equality>
    <joint name="gripper_gear" joint1="joint6" joint2="joint6M" polycoef="0 1 0 0 0" solref="0.001 1" solimp="0.99 0.999 0.001"/>
  </equality>

  <actuator>
    <!-- Velocity control actuators -->
    <velocity joint="base_x" kv="100"/>
    <velocity joint="base_y" kv="100"/>
    <velocity joint="base_yaw" kv="100"/>
    
    <!-- Position control actuators for the arm joints -->
    <position joint="joint1" kp="1000"/>
    <position joint="joint2" kp="1000"/>
    <position joint="joint3" kp="1000"/>
    <position joint="joint4" kp="1000"/>
    <position joint="joint5" kp="1000"/>
    <position joint="joint6" kp="1000"/>
    <!-- joint6M is controlled via equality constraint, no separate actuator needed -->
  </actuator>
</mujoco>
